Workbook

Sheet Monthly
A1: YEAR | B1: MONTH | C1: DATE | D1: PASSENGER_CAR_REGISTRATIONS | E1: MOTOR_VEHICLE_PROD_INDEX_2021 | F1: HICP_MOTOR_CARS | G1: INTEREST_RATE_HOUSEHOLD_CONSUMPTION | H1: QUARTER_NUM | I1: QUARTER_YEAR | J1: QUARTER_END_DATE
A2: =+YEAR(C2) -> 2016 | B2: =+_xlfn.NUMBERVALUE(MONTH(C2)) -> 1 | C2: 42400 | D2: 791536 | E2: 122.4 | F2: 100.35 | G2: 6.15 | H2: 1 | I2: =+A2&"Q"&H2 -> 2016Q1 | J2: =+EOMONTH(DATE(A2,3,1),0) -> 42460
A3: =+YEAR(C3) -> 2016 | B3: =+_xlfn.NUMBERVALUE(MONTH(C3)) -> 2 | C3: 42429 | D3: 864048 | E3: 135.6 | F3: 100.35 | G3: 5.97 | H3: 1 | I3: =+A3&"Q"&H3 -> 2016Q1 | J3: =+EOMONTH(DATE(A3,3,1),0) -> 42460
A4: =+YEAR(C4) -> 2016 | B4: =+_xlfn.NUMBERVALUE(MONTH(C4)) -> 3 | C4: 42460 | D4: 1050602 | E4: 146.5 | F4: 100.49 | G4: 5.86 | H4: 1 | I4: =+A4&"Q"&H4 -> 2016Q1 | J4: =+EOMONTH(DATE(A4,3,1),0) -> 42460
A5: =+YEAR(C5) -> 2016 | B5: =+_xlfn.NUMBERVALUE(MONTH(C5)) -> 4 | C5: 42490 | D5: 957676 | E5: 139.5 | F5: 100.29 | G5: 5.9 | H5: 2 | I5: =+A5&"Q"&H5 -> 2016Q2 | J5: =+EOMONTH(DATE(A5,6,1),0) -> 42551
A6: =+YEAR(C6) -> 2016 | B6: =+_xlfn.NUMBERVALUE(MONTH(C6)) -> 5 | C6: 42521 | D6: 955271 | E6: 128.8 | F6: 100.25 | G6: 5.98 | H6: 2 | I6: =+A6&"Q"&H6 -> 2016Q2 | J6: =+EOMONTH(DATE(A6,6,1),0) -> 42551
A7: =+YEAR(C7) -> 2016 | B7: =+_xlfn.NUMBERVALUE(MONTH(C7)) -> 6 | C7: 42551 | D7: 1062822 | E7: 139.6 | F7: 100.22 | G7: 5.75 | H7: 2 | I7: =+A7&"Q"&H7 -> 2016Q2 | J7: =+EOMONTH(DATE(A7,6,1),0) -> 42551
A8: =+YEAR(C8) -> 2016 | B8: =+_xlfn.NUMBERVALUE(MONTH(C8)) -> 7 | C8: 42582 | D8: 835146 | E8: 130 | F8: 100.22 | G8: 5.86 | H8: 3 | I8: =+A8&"Q"&H8 -> 2016Q3 | J8: =+EOMONTH(DATE(A8,9,1),0) -> 42643
A9: =+YEAR(C9) -> 2016 | B9: =+_xlfn.NUMBERVALUE(MONTH(C9)) -> 8 | C9: 42613 | D9: 621788 | E9: 100.7 | F9: 100.21 | G9: 5.93 | H9: 3 | I9: =+A9&"Q"&H9 -> 2016Q3 | J9: =+EOMONTH(DATE(A9,9,1),0) -> 42643
A10: =+YEAR(C10) -> 2016 | B10: =+_xlfn.NUMBERVALUE(MONTH(C10)) -> 9 | C10: 42643 | D10: 862973 | E10: 141.3 | F10: 100.28 | G10: 5.67 | H10: 3 | I10: =+A10&"Q"&H10 -> 2016Q3 | J10: =+EOMONTH(DATE(A10,9,1),0) -> 42643
A11: =+YEAR(C11) -> 2016 | B11: =+_xlfn.NUMBERVALUE(MONTH(C11)) -> 10 | C11: 42674 | D11: 803093 | E11: 141.6 | F11: 100.27 | G11: 5.61 | H11: 4 | I11: =+A11&"Q"&H11 -> 2016Q4 | J11: =+EOMONTH(DATE(A11,12,1),0) -> 42735
A12: =+YEAR(C12) -> 2016 | B12: =+_xlfn.NUMBERVALUE(MONTH(C12)) -> 11 | C12: 42704 | D12: 833682 | E12: 140 | F12: 100.27 | G12: 5.62 | H12: 4 | I12: =+A12&"Q"&H12 -> 2016Q4 | J12: =+EOMONTH(DATE(A12,12,1),0) -> 42735
A13: =+YEAR(C13) -> 2016 | B13: =+_xlfn.NUMBERVALUE(MONTH(C13)) -> 12 | C13: 42735 | D13: 821131 | E13: 100.6 | F13: 100.23 | G13: 5.38 | H13: 4 | I13: =+A13&"Q"&H13 -> 2016Q4 | J13: =+EOMONTH(DATE(A13,12,1),0) -> 42735
A14: =+YEAR(C14) -> 2017 | B14: =+_xlfn.NUMBERVALUE(MONTH(C14)) -> 1 | C14: 42766 | D14: 878700 | E14: 120.3 | F14: 100.65 | G14: 5.77 | H14: 1 | I14: =+A14&"Q"&H14 -> 2017Q1 | J14: =+EOMONTH(DATE(A14,3,1),0) -> 42825
A15: =+YEAR(C15) -> 2017 | B15: =+_xlfn.NUMBERVALUE(MONTH(C15)) -> 2 | C15: 42794 | D15: 873256 | E15: 135 | F15: 100.86 | G15: 5.65 | H15: 1 | I15: =+A15&"Q"&H15 -> 2017Q1 | J15: =+EOMONTH(DATE(A15,3,1),0) -> 42825
A16: =+YEAR(C16) -> 2017 | B16: =+_xlfn.NUMBERVALUE(MONTH(C16)) -> 3 | C16: 42825 | D16: 1172456 | E16: 148 | F16: 100.9 | G16: 5.55 | H16: 1 | I16: =+A16&"Q"&H16 -> 2017Q1 | J16: =+EOMONTH(DATE(A16,3,1),0) -> 42825
A17: =+YEAR(C17) -> 2017 | B17: =+_xlfn.NUMBERVALUE(MONTH(C17)) -> 4 | C17: 42855 | D17: 911307 | E17: 134.3 | F17: 100.95 | G17: 5.49 | H17: 2 | I17: =+A17&"Q"&H17 -> 2017Q2 | J17: =+EOMONTH(DATE(A17,6,1),0) -> 42916
A18: =+YEAR(C18) -> 2017 | B18: =+_xlfn.NUMBERVALUE(MONTH(C18)) -> 5 | C18: 42886 | D18: 1055359 | E18: 136.6 | F18: 100.93 | G18: 5.7 | H18: 2 | I18: =+A18&"Q"&H18 -> 2017Q2 | J18: =+EOMONTH(DATE(A18,6,1),0) -> 42916
A19: =+YEAR(C19) -> 2017 | B19: =+_xlfn.NUMBERVALUE(MONTH(C19)) -> 6 | C19: 42916 | D19: 1095090 | E19: 138 | F19: 100.83 | G19: 5.62 | H19: 2 | I19: =+A19&"Q"&H19 -> 2017Q2 | J19: =+EOMONTH(DATE(A19,6,1),0) -> 42916
A20: =+YEAR(C20) -> 2017 | B20: =+_xlfn.NUMBERVALUE(MONTH(C20)) -> 7 | C20: 42947 | D20: 873937 | E20: 132.8 | F20: 100.94 | G20: 5.74 | H20: 3 | I20: =+A20&"Q"&H20 -> 2017Q3 | J20: =+EOMONTH(DATE(A20,9,1),0) -> 43008
A21: =+YEAR(C21) -> 2017 | B21: =+_xlfn.NUMBERVALUE(MONTH(C21)) -> 8 | C21: 42978 | D21: 664156 | E21: 107.3 | F21: 101 | G21: 5.82 | H21: 3 | I21: =+A21&"Q"&H21 -> 2017Q3 | J21: =+EOMONTH(DATE(A21,9,1),0) -> 43008
A22: =+YEAR(C22) -> 2017 | B22: =+_xlfn.NUMBERVALUE(MONTH(C22)) -> 9 | C22: 43008 | D22: 874901 | E22: 147.7 | F22: 101.06 | G22: 5.64 | H22: 3 | I22: =+A22&"Q"&H22 -> 2017Q3 | J22: =+EOMONTH(DATE(A22,9,1),0) -> 43008
A23: =+YEAR(C23) -> 2017 | B23: =+_xlfn.NUMBERVALUE(MONTH(C23)) -> 10 | C23: 43039 | D23: 873496 | E23: 141.2 | F23: 101.1 | G23: 5.6 | H23: 4 | I23: =+A23&"Q"&H23 -> 2017Q4 | J23: =+EOMONTH(DATE(A23,12,1),0) -> 43100
A24: =+YEAR(C24) -> 2017 | B24: =+_xlfn.NUMBERVALUE(MONTH(C24)) -> 11 | C24: 43069 | D24: 914144 | E24: 152.7 | F24: 101.25 | G24: 5.57 | H24: 4 | I24: =+A24&"Q"&H24 -> 2017Q4 | J24: =+EOMONTH(DATE(A24,12,1),0) -> 43100
A25: =+YEAR(C25) -> 2017 | B25: =+_xlfn.NUMBERVALUE(MONTH(C25)) -> 12 | C25: 43100 | D25: 796098 | E25: 109.3 | F25: 101.28 | G25: 5.26 | H25: 4 | I25: =+A25&"Q"&H25 -> 2017Q4 | J25: =+EOMONTH(DATE(A25,12,1),0) -> 43100
A26: =+YEAR(C26) -> 2018 | B26: =+_xlfn.NUMBERVALUE(MONTH(C26)) -> 1 | C26: 43131 | D26: 954680 | E26: 127.8 | F26: 101.51 | G26: 5.74 | H26: 1 | I26: =+A26&"Q"&H26 -> 2018Q1 | J26: =+EOMONTH(DATE(A26,3,1),0) -> 43190
A27: =+YEAR(C27) -> 2018 | B27: =+_xlfn.NUMBERVALUE(MONTH(C27)) -> 2 | C27: 43159 | D27: 916540 | E27: 135.4 | F27: 101.62 | G27: 5.59 | H27: 1 | I27: =+A27&"Q"&H27 -> 2018Q1 | J27: =+EOMONTH(DATE(A27,3,1),0) -> 43190
A28: =+YEAR(C28) -> 2018 | B28: =+_xlfn.NUMBERVALUE(MONTH(C28)) -> 3 | C28: 43190 | D28: 1161539 | E28: 156.3 | F28: 101.82 | G28: 5.47 | H28: 1 | I28: =+A28&"Q"&H28 -> 2018Q1 | J28: =+EOMONTH(DATE(A28,3,1),0) -> 43190
A29: =+YEAR(C29) -> 2018 | B29: =+_xlfn.NUMBERVALUE(MONTH(C29)) -> 4 | C29: 43220 | D29: 996616 | E29: 141.5 | F29: 101.95 | G29: 5.6 | H29: 2 | I29: =+A29&"Q"&H29 -> 2018Q2 | J29: =+EOMONTH(DATE(A29,6,1),0) -> 43281
A30: =+YEAR(C30) -> 2018 | B30: =+_xlfn.NUMBERVALUE(MONTH(C30)) -> 5 | C30: 43251 | D30: 1050604 | E30: 138.9 | F30: 102.23 | G30: 5.77 | H30: 2 | I30: =+A30&"Q"&H30 -> 2018Q2 | J30: =+EOMONTH(DATE(A30,6,1),0) -> 43281
A31: =+YEAR(C31) -> 2018 | B31: =+_xlfn.NUMBERVALUE(MONTH(C31)) -> 6 | C31: 43281 | D31: 1143602 | E31: 144 | F31: 102.27 | G31: 5.51 | H31: 2 | I31: =+A31&"Q"&H31 -> 2018Q2 | J31: =+EOMONTH(DATE(A31,6,1),0) -> 43281
A32: =+YEAR(C32) -> 2018 | B32: =+_xlfn.NUMBERVALUE(MONTH(C32)) -> 7 | C32: 43312 | D32: 986437 | E32: 129.4 | F32: 102.41 | G32: 5.65 | H32: 3 | I32: =+A32&"Q"&H32 -> 2018Q3 | J32: =+EOMONTH(DATE(A32,9,1),0) -> 43373
A33: =+YEAR(C33) -> 2018 | B33: =+_xlfn.NUMBERVALUE(MONTH(C33)) -> 8 | C33: 43343 | D33: 868770 | E33: 94.7 | F33: 102.52 | G33: 5.83 | H33: 3 | I33: =+A33&"Q"&H33 -> 2018Q3 | J33: =+EOMONTH(DATE(A33,9,1),0) -> 43373
A34: =+YEAR(C34) -> 2018 | B34: =+_xlfn.NUMBERVALUE(MONTH(C34)) -> 9 | C34: 43373 | D34: 665121 | E34: 137.5 | F34: 102.65 | G34: 5.69 | H34: 3 | I34: =+A34&"Q"&H34 -> 2018Q3 | J34: =+EOMONTH(DATE(A34,9,1),0) -> 43373
A35: =+YEAR(C35) -> 2018 | B35: =+_xlfn.NUMBERVALUE(MONTH(C35)) -> 10 | C35: 43404 | D35: 810505 | E35: 136.2 | F35: 102.76 | G35: 5.64 | H35: 4 | I35: =+A35&"Q"&H35 -> 2018Q4 | J35: =+EOMONTH(DATE(A35,12,1),0) -> 43465
A36: =+YEAR(C36) -> 2018 | B36: =+_xlfn.NUMBERVALUE(MONTH(C36)) -> 11 | C36: 43434 | D36: 834062 | E36: 136.8 | F36: 102.89 | G36: 5.58 | H36: 4 | I36: =+A36&"Q"&H36 -> 2018Q4 | J36: =+EOMONTH(DATE(A36,12,1),0) -> 43465
A37: =+YEAR(C37) -> 2018 | B37: =+_xlfn.NUMBERVALUE(MONTH(C37)) -> 12 | C37: 43465 | D37: 736209 | E37: 106.2 | F37: 103.15 | G37: 5.39 | H37: 4 | I37: =+A37&"Q"&H37 -> 2018Q4 | J37: =+EOMONTH(DATE(A37,12,1),0) -> 43465
A38: =+YEAR(C38) -> 2019 | B38: =+_xlfn.NUMBERVALUE(MONTH(C38)) -> 1 | C38: 43496 | D38: 901399 | E38: 117.7 | F38: 103.3 | G38: 5.76 | H38: 1 | I38: =+A38&"Q"&H38 -> 2019Q1 | J38: =+EOMONTH(DATE(A38,3,1),0) -> 43555
A39: =+YEAR(C39) -> 2019 | B39: =+_xlfn.NUMBERVALUE(MONTH(C39)) -> 2 | C39: 43524 | D39: 902821 | E39: 133.5 | F39: 103.43 | G39: 5.66 | H39: 1 | I39: =+A39&"Q"&H39 -> 2019Q1 | J39: =+EOMONTH(DATE(A39,3,1),0) -> 43555
A40: =+YEAR(C40) -> 2019 | B40: =+_xlfn.NUMBERVALUE(MONTH(C40)) -> 3 | C40: 43555 | D40: 1109915 | E40: 145.3 | F40: 103.55 | G40: 5.59 | H40: 1 | I40: =+A40&"Q"&H40 -> 2019Q1 | J40: =+EOMONTH(DATE(A40,3,1),0) -> 43555
...

Sheet Quarterly
A1: YEAR | B1: QUARTER_NUM | C1: QUARTER_YEAR | D1: QUARTER_END_DATE | E1: PASSENGER_CAR_REGISTRATIONS | F1: MOTOR_VEHICLE_PROD_INDEX_2021 | G1: HICP_MOTOR_CARS | H1: INTEREST_RATE_HOUSEHOLD_CONSUMPTION | I1: GDP | J1: POST_CO2_STANDARDS_2019 | K1: TRAVEL_BAN_COVID
A2: 2016 | B2: 1 | C2: =+A2&"Q"&B2 -> 2016Q1 | D2: =+EOMONTH(DATE(A2,3,1),0) -> 42460 | E2: =+SUMIFS(Monthly!$D$2:$D$109,Monthly!$J$2:$J$109,Quarterly!D2) -> 2706186 | F2: =+AVERAGEIFS(Monthly!$E$2:$E$109,Monthly!$J$2:$J$109,Quarterly!D2) -> 134.83333 | G2: =+AVERAGEIFS(Monthly!$F$2:$F$109,Monthly!$J$2:$J$109,Quarterly!D2) -> 100.39667 | H2: =+AVERAGEIFS(Monthly!$G$2:$G$109,Monthly!$J$2:$J$109,Quarterly!D2) -> 5.9933333 | I2: 2541092.7 | J2: 0 | K2: 0
A3: 2016 | B3: 2 | C3: =+A3&"Q"&B3 -> 2016Q2 | D3: =+EOMONTH(DATE(A3,6,1),0) -> 42551 | E3: =+SUMIFS(Monthly!$D$2:$D$109,Monthly!$J$2:$J$109,Quarterly!D3) -> 2975769 | F3: =+AVERAGEIFS(Monthly!$E$2:$E$109,Monthly!$J$2:$J$109,Quarterly!D3) -> 135.96667 | G3: =+AVERAGEIFS(Monthly!$F$2:$F$109,Monthly!$J$2:$J$109,Quarterly!D3) -> 100.25333 | H3: =+AVERAGEIFS(Monthly!$G$2:$G$109,Monthly!$J$2:$J$109,Quarterly!D3) -> 5.8766667 | I3: 2545975.1 | J3: 0 | K3: 0
A4: 2016 | B4: 3 | C4: =+A4&"Q"&B4 -> 2016Q3 | D4: =+EOMONTH(DATE(A4,9,1),0) -> 42643 | E4: =+SUMIFS(Monthly!$D$2:$D$109,Monthly!$J$2:$J$109,Quarterly!D4) -> 2319907 | F4: =+AVERAGEIFS(Monthly!$E$2:$E$109,Monthly!$J$2:$J$109,Quarterly!D4) -> 124 | G4: =+AVERAGEIFS(Monthly!$F$2:$F$109,Monthly!$J$2:$J$109,Quarterly!D4) -> 100.23667 | H4: =+AVERAGEIFS(Monthly!$G$2:$G$109,Monthly!$J$2:$J$109,Quarterly!D4) -> 5.82 | I4: 2558295.2 | J4: 0 | K4: 0
A5: 2016 | B5: 4 | C5: =+A5&"Q"&B5 -> 2016Q4 | D5: =+EOMONTH(DATE(A5,12,1),0) -> 42735 | E5: =+SUMIFS(Monthly!$D$2:$D$109,Monthly!$J$2:$J$109,Quarterly!D5) -> 2457906 | F5: =+AVERAGEIFS(Monthly!$E$2:$E$109,Monthly!$J$2:$J$109,Quarterly!D5) -> 127.4 | G5: =+AVERAGEIFS(Monthly!$F$2:$F$109,Monthly!$J$2:$J$109,Quarterly!D5) -> 100.25667 | H5: =+AVERAGEIFS(Monthly!$G$2:$G$109,Monthly!$J$2:$J$109,Quarterly!D5) -> 5.5366667 | I5: 2577850.2 | J5: 0 | K5: 0
A6: 2017 | B6: 1 | C6: =+A6&"Q"&B6 -> 2017Q1 | D6: =+EOMONTH(DATE(A6,3,1),0) -> 42825 | E6: =+SUMIFS(Monthly!$D$2:$D$109,Monthly!$J$2:$J$109,Quarterly!D6) -> 2924412 | F6: =+AVERAGEIFS(Monthly!$E$2:$E$109,Monthly!$J$2:$J$109,Quarterly!D6) -> 134.43333 | G6: =+AVERAGEIFS(Monthly!$F$2:$F$109,Monthly!$J$2:$J$109,Quarterly!D6) -> 100.80333 | H6: =+AVERAGEIFS(Monthly!$G$2:$G$109,Monthly!$J$2:$J$109,Quarterly!D6) -> 5.6566667 | I6: 2598643.9 | J6: 0 | K6: 0
A7: 2017 | B7: 2 | C7: =+A7&"Q"&B7 -> 2017Q2 | D7: =+EOMONTH(DATE(A7,6,1),0) -> 42916 | E7: =+SUMIFS(Monthly!$D$2:$D$109,Monthly!$J$2:$J$109,Quarterly!D7) -> 3061756 | F7: =+AVERAGEIFS(Monthly!$E$2:$E$109,Monthly!$J$2:$J$109,Quarterly!D7) -> 136.3 | G7: =+AVERAGEIFS(Monthly!$F$2:$F$109,Monthly!$J$2:$J$109,Quarterly!D7) -> 100.90333 | H7: =+AVERAGEIFS(Monthly!$G$2:$G$109,Monthly!$J$2:$J$109,Quarterly!D7) -> 5.6033333 | I7: 2615876.3 | J7: 0 | K7: 0
A8: 2017 | B8: 3 | C8: =+A8&"Q"&B8 -> 2017Q3 | D8: =+EOMONTH(DATE(A8,9,1),0) -> 43008 | E8: =+SUMIFS(Monthly!$D$2:$D$109,Monthly!$J$2:$J$109,Quarterly!D8) -> 2412994 | F8: =+AVERAGEIFS(Monthly!$E$2:$E$109,Monthly!$J$2:$J$109,Quarterly!D8) -> 129.26667 | G8: =+AVERAGEIFS(Monthly!$F$2:$F$109,Monthly!$J$2:$J$109,Quarterly!D8) -> 101 | H8: =+AVERAGEIFS(Monthly!$G$2:$G$109,Monthly!$J$2:$J$109,Quarterly!D8) -> 5.7333333 | I8: 2635049.5 | J8: 0 | K8: 0
A9: 2017 | B9: 4 | C9: =+A9&"Q"&B9 -> 2017Q4 | D9: =+EOMONTH(DATE(A9,12,1),0) -> 43100 | E9: =+SUMIFS(Monthly!$D$2:$D$109,Monthly!$J$2:$J$109,Quarterly!D9) -> 2583738 | F9: =+AVERAGEIFS(Monthly!$E$2:$E$109,Monthly!$J$2:$J$109,Quarterly!D9) -> 134.4 | G9: =+AVERAGEIFS(Monthly!$F$2:$F$109,Monthly!$J$2:$J$109,Quarterly!D9) -> 101.21 | H9: =+AVERAGEIFS(Monthly!$G$2:$G$109,Monthly!$J$2:$J$109,Quarterly!D9) -> 5.4766667 | I9: 2656496.8 | J9: 0 | K9: 0
A10: 2018 | B10: 1 | C10: =+A10&"Q"&B10 -> 2018Q1 | D10: =+EOMONTH(DATE(A10,3,1),0) -> 43190 | E10: =+SUMIFS(Monthly!$D$2:$D$109,Monthly!$J$2:$J$109,Quarterly!D10) -> 3032759 | F10: =+AVERAGEIFS(Monthly!$E$2:$E$109,Monthly!$J$2:$J$109,Quarterly!D10) -> 139.83333 | G10: =+AVERAGEIFS(Monthly!$F$2:$F$109,Monthly!$J$2:$J$109,Quarterly!D10) -> 101.65 | H10: =+AVERAGEIFS(Monthly!$G$2:$G$109,Monthly!$J$2:$J$109,Quarterly!D10) -> 5.6 | I10: 2657658.8 | J10: 0 | K10: 0
A11: 2018 | B11: 2 | C11: =+A11&"Q"&B11 -> 2018Q2 | D11: =+EOMONTH(DATE(A11,6,1),0) -> 43281 | E11: =+SUMIFS(Monthly!$D$2:$D$109,Monthly!$J$2:$J$109,Quarterly!D11) -> 3190822 | F11: =+AVERAGEIFS(Monthly!$E$2:$E$109,Monthly!$J$2:$J$109,Quarterly!D11) -> 141.46667 | G11: =+AVERAGEIFS(Monthly!$F$2:$F$109,Monthly!$J$2:$J$109,Quarterly!D11) -> 102.15 | H11: =+AVERAGEIFS(Monthly!$G$2:$G$109,Monthly!$J$2:$J$109,Quarterly!D11) -> 5.6266667 | I11: 2671288.3 | J11: 0 | K11: 0
A12: 2018 | B12: 3 | C12: =+A12&"Q"&B12 -> 2018Q3 | D12: =+EOMONTH(DATE(A12,9,1),0) -> 43373 | E12: =+SUMIFS(Monthly!$D$2:$D$109,Monthly!$J$2:$J$109,Quarterly!D12) -> 2520328 | F12: =+AVERAGEIFS(Monthly!$E$2:$E$109,Monthly!$J$2:$J$109,Quarterly!D12) -> 120.53333 | G12: =+AVERAGEIFS(Monthly!$F$2:$F$109,Monthly!$J$2:$J$109,Quarterly!D12) -> 102.52667 | H12: =+AVERAGEIFS(Monthly!$G$2:$G$109,Monthly!$J$2:$J$109,Quarterly!D12) -> 5.7233333 | I12: 2673362.3 | J12: 0 | K12: 0
A13: 2018 | B13: 4 | C13: =+A13&"Q"&B13 -> 2018Q4 | D13: =+EOMONTH(DATE(A13,12,1),0) -> 43465 | E13: =+SUMIFS(Monthly!$D$2:$D$109,Monthly!$J$2:$J$109,Quarterly!D13) -> 2380776 | F13: =+AVERAGEIFS(Monthly!$E$2:$E$109,Monthly!$J$2:$J$109,Quarterly!D13) -> 126.4 | G13: =+AVERAGEIFS(Monthly!$F$2:$F$109,Monthly!$J$2:$J$109,Quarterly!D13) -> 102.93333 | H13: =+AVERAGEIFS(Monthly!$G$2:$G$109,Monthly!$J$2:$J$109,Quarterly!D13) -> 5.5366667 | I13: 2687802.8 | J13: 0 | K13: 0
A14: 2019 | B14: 1 | C14: =+A14&"Q"&B14 -> 2019Q1 | D14: =+EOMONTH(DATE(A14,3,1),0) -> 43555 | E14: =+SUMIFS(Monthly!$D$2:$D$109,Monthly!$J$2:$J$109,Quarterly!D14) -> 2914135 | F14: =+AVERAGEIFS(Monthly!$E$2:$E$109,Monthly!$J$2:$J$109,Quarterly!D14) -> 132.16667 | G14: =+AVERAGEIFS(Monthly!$F$2:$F$109,Monthly!$J$2:$J$109,Quarterly!D14) -> 103.42667 | H14: =+AVERAGEIFS(Monthly!$G$2:$G$109,Monthly!$J$2:$J$109,Quarterly!D14) -> 5.67 | I14: 2707181.1 | J14: 0 | K14: 0
A15: 2019 | B15: 2 | C15: =+A15&"Q"&B15 -> 2019Q2 | D15: =+EOMONTH(DATE(A15,6,1),0) -> 43646 | E15: =+SUMIFS(Monthly!$D$2:$D$109,Monthly!$J$2:$J$109,Quarterly!D15) -> 3139990 | F15: =+AVERAGEIFS(Monthly!$E$2:$E$109,Monthly!$J$2:$J$109,Quarterly!D15) -> 134.2 | G15: =+AVERAGEIFS(Monthly!$F$2:$F$109,Monthly!$J$2:$J$109,Quarterly!D15) -> 103.58667 | H15: =+AVERAGEIFS(Monthly!$G$2:$G$109,Monthly!$J$2:$J$109,Quarterly!D15) -> 5.6666667 | I15: 2716970.9 | J15: 0 | K15: 0
A16: 2019 | B16: 3 | C16: =+A16&"Q"&B16 -> 2019Q3 | D16: =+EOMONTH(DATE(A16,9,1),0) -> 43738 | E16: =+SUMIFS(Monthly!$D$2:$D$109,Monthly!$J$2:$J$109,Quarterly!D16) -> 2564660 | F16: =+AVERAGEIFS(Monthly!$E$2:$E$109,Monthly!$J$2:$J$109,Quarterly!D16) -> 119.16667 | G16: =+AVERAGEIFS(Monthly!$F$2:$F$109,Monthly!$J$2:$J$109,Quarterly!D16) -> 103.55333 | H16: =+AVERAGEIFS(Monthly!$G$2:$G$109,Monthly!$J$2:$J$109,Quarterly!D16) -> 5.7166667 | I16: 2722063.3 | J16: 0 | K16: 0
A17: 2019 | B17: 4 | C17: =+A17&"Q"&B17 -> 2019Q4 | D17: =+EOMONTH(DATE(A17,12,1),0) -> 43830 | E17: =+SUMIFS(Monthly!$D$2:$D$109,Monthly!$J$2:$J$109,Quarterly!D17) -> 2667983 | F17: =+AVERAGEIFS(Monthly!$E$2:$E$109,Monthly!$J$2:$J$109,Quarterly!D17) -> 120.26667 | G17: =+AVERAGEIFS(Monthly!$F$2:$F$109,Monthly!$J$2:$J$109,Quarterly!D17) -> 103.88 | H17: =+AVERAGEIFS(Monthly!$G$2:$G$109,Monthly!$J$2:$J$109,Quarterly!D17) -> 5.46 | I17: 2719294.5 | J17: 0 | K17: 0
A18: 2020 | B18: 1 | C18: =+A18&"Q"&B18 -> 2020Q1 | D18: =+EOMONTH(DATE(A18,3,1),0) -> 43921 | E18: =+SUMIFS(Monthly!$D$2:$D$109,Monthly!$J$2:$J$109,Quarterly!D18) -> 2140735 | F18: =+AVERAGEIFS(Monthly!$E$2:$E$109,Monthly!$J$2:$J$109,Quarterly!D18) -> 111.8 | G18: =+AVERAGEIFS(Monthly!$F$2:$F$109,Monthly!$J$2:$J$109,Quarterly!D18) -> 104.39 | H18: =+AVERAGEIFS(Monthly!$G$2:$G$109,Monthly!$J$2:$J$109,Quarterly!D18) -> 5.57 | I18: 2630897.8 | J18: 1 | K18: 0
A19: 2020 | B19: 2 | C19: =+A19&"Q"&B19 -> 2020Q2 | D19: =+EOMONTH(DATE(A19,6,1),0) -> 44012 | E19: =+SUMIFS(Monthly!$D$2:$D$109,Monthly!$J$2:$J$109,Quarterly!D19) -> 1536623 | F19: =+AVERAGEIFS(Monthly!$E$2:$E$109,Monthly!$J$2:$J$109,Quarterly!D19) -> 62.133333 | G19: =+AVERAGEIFS(Monthly!$F$2:$F$109,Monthly!$J$2:$J$109,Quarterly!D19) -> 104.70333 | H19: =+AVERAGEIFS(Monthly!$G$2:$G$109,Monthly!$J$2:$J$109,Quarterly!D19) -> 5.1 | I19: 2338460.5 | J19: 1 | K19: 1
A20: 2020 | B20: 3 | C20: =+A20&"Q"&B20 -> 2020Q3 | D20: =+EOMONTH(DATE(A20,9,1),0) -> 44104 | E20: =+SUMIFS(Monthly!$D$2:$D$109,Monthly!$J$2:$J$109,Quarterly!D20) -> 2400935 | F20: =+AVERAGEIFS(Monthly!$E$2:$E$109,Monthly!$J$2:$J$109,Quarterly!D20) -> 103.5 | G20: =+AVERAGEIFS(Monthly!$F$2:$F$109,Monthly!$J$2:$J$109,Quarterly!D20) -> 104.59667 | H20: =+AVERAGEIFS(Monthly!$G$2:$G$109,Monthly!$J$2:$J$109,Quarterly!D20) -> 5.26 | I20: 2608372 | J20: 1 | K20: 1
A21: 2020 | B21: 4 | C21: =+A21&"Q"&B21 -> 2020Q4 | D21: =+EOMONTH(DATE(A21,12,1),0) -> 44196 | E21: =+SUMIFS(Monthly!$D$2:$D$109,Monthly!$J$2:$J$109,Quarterly!D21) -> 2463225 | F21: =+AVERAGEIFS(Monthly!$E$2:$E$109,Monthly!$J$2:$J$109,Quarterly!D21) -> 123.53333 | G21: =+AVERAGEIFS(Monthly!$F$2:$F$109,Monthly!$J$2:$J$109,Quarterly!D21) -> 104.9 | H21: =+AVERAGEIFS(Monthly!$G$2:$G$109,Monthly!$J$2:$J$109,Quarterly!D21) -> 5.1766667 | I21: 2617997.5 | J21: 1 | K21: 1
A22: 2021 | B22: 1 | C22: =+A22&"Q"&B22 -> 2021Q1 | D22: =+EOMONTH(DATE(A22,3,1),0) -> 44286 | E22: =+SUMIFS(Monthly!$D$2:$D$109,Monthly!$J$2:$J$109,Quarterly!D22) -> 2199573 | F22: =+AVERAGEIFS(Monthly!$E$2:$E$109,Monthly!$J$2:$J$109,Quarterly!D22) -> 115.33333 | G22: =+AVERAGEIFS(Monthly!$F$2:$F$109,Monthly!$J$2:$J$109,Quarterly!D22) -> 106.21333 | H22: =+AVERAGEIFS(Monthly!$G$2:$G$109,Monthly!$J$2:$J$109,Quarterly!D22) -> 5.1966667 | I22: 2638667.1 | J22: 1 | K22: 1
A23: 2021 | B23: 2 | C23: =+A23&"Q"&B23 -> 2021Q2 | D23: =+EOMONTH(DATE(A23,6,1),0) -> 44377 | E23: =+SUMIFS(Monthly!$D$2:$D$109,Monthly!$J$2:$J$109,Quarterly!D23) -> 2411778 | F23: =+AVERAGEIFS(Monthly!$E$2:$E$109,Monthly!$J$2:$J$109,Quarterly!D23) -> 102.46667 | G23: =+AVERAGEIFS(Monthly!$F$2:$F$109,Monthly!$J$2:$J$109,Quarterly!D23) -> 107.05667 | H23: =+AVERAGEIFS(Monthly!$G$2:$G$109,Monthly!$J$2:$J$109,Quarterly!D23) -> 5.2133333 | I23: 2695934.9 | J23: 1 | K23: 1
A24: 2021 | B24: 3 | C24: =+A24&"Q"&B24 -> 2021Q3 | D24: =+EOMONTH(DATE(A24,9,1),0) -> 44469 | E24: =+SUMIFS(Monthly!$D$2:$D$109,Monthly!$J$2:$J$109,Quarterly!D24) -> 1832209 | F24: =+AVERAGEIFS(Monthly!$E$2:$E$109,Monthly!$J$2:$J$109,Quarterly!D24) -> 81.8 | G24: =+AVERAGEIFS(Monthly!$F$2:$F$109,Monthly!$J$2:$J$109,Quarterly!D24) -> 108.10667 | H24: =+AVERAGEIFS(Monthly!$G$2:$G$109,Monthly!$J$2:$J$109,Quarterly!D24) -> 5.29 | I24: 2743277.5 | J24: 1 | K24: 1
A25: 2021 | B25: 4 | C25: =+A25&"Q"&B25 -> 2021Q4 | D25: =+EOMONTH(DATE(A25,12,1),0) -> 44561 | E25: =+SUMIFS(Monthly!$D$2:$D$109,Monthly!$J$2:$J$109,Quarterly!D25) -> 1849030 | F25: =+AVERAGEIFS(Monthly!$E$2:$E$109,Monthly!$J$2:$J$109,Quarterly!D25) -> 100.43333 | G25: =+AVERAGEIFS(Monthly!$F$2:$F$109,Monthly!$J$2:$J$109,Quarterly!D25) -> 109.91333 | H25: =+AVERAGEIFS(Monthly!$G$2:$G$109,Monthly!$J$2:$J$109,Quarterly!D25) -> 5.1666667 | I25: 2765397.4 | J25: 1 | K25: 1
A26: 2022 | B26: 1 | C26: =+A26&"Q"&B26 -> 2022Q1 | D26: =+EOMONTH(DATE(A26,3,1),0) -> 44651 | E26: =+SUMIFS(Monthly!$D$2:$D$109,Monthly!$J$2:$J$109,Quarterly!D26) -> 1928306 | F26: =+AVERAGEIFS(Monthly!$E$2:$E$109,Monthly!$J$2:$J$109,Quarterly!D26) -> 100.53333 | G26: =+AVERAGEIFS(Monthly!$F$2:$F$109,Monthly!$J$2:$J$109,Quarterly!D26) -> 112.66333 | H26: =+AVERAGEIFS(Monthly!$G$2:$G$109,Monthly!$J$2:$J$109,Quarterly!D26) -> 5.27 | I26: 2785642.9 | J26: 1 | K26: 1
A27: 2022 | B27: 2 | C27: =+A27&"Q"&B27 -> 2022Q2 | D27: =+EOMONTH(DATE(A27,6,1),0) -> 44742 | E27: =+SUMIFS(Monthly!$D$2:$D$109,Monthly!$J$2:$J$109,Quarterly!D27) -> 2020598 | F27: =+AVERAGEIFS(Monthly!$E$2:$E$109,Monthly!$J$2:$J$109,Quarterly!D27) -> 103.83333 | G27: =+AVERAGEIFS(Monthly!$F$2:$F$109,Monthly!$J$2:$J$109,Quarterly!D27) -> 115.35667 | H27: =+AVERAGEIFS(Monthly!$G$2:$G$109,Monthly!$J$2:$J$109,Quarterly!D27) -> 5.5233333 | I27: 2811827 | J27: 1 | K27: 1
A28: 2022 | B28: 3 | C28: =+A28&"Q"&B28 -> 2022Q3 | D28: =+EOMONTH(DATE(A28,9,1),0) -> 44834 | E28: =+SUMIFS(Monthly!$D$2:$D$109,Monthly!$J$2:$J$109,Quarterly!D28) -> 1858875 | F28: =+AVERAGEIFS(Monthly!$E$2:$E$109,Monthly!$J$2:$J$109,Quarterly!D28) -> 99.733333 | G28: =+AVERAGEIFS(Monthly!$F$2:$F$109,Monthly!$J$2:$J$109,Quarterly!D28) -> 117.74667 | H28: =+AVERAGEIFS(Monthly!$G$2:$G$109,Monthly!$J$2:$J$109,Quarterly!D28) -> 5.9133333 | I28: 2824456.4 | J28: 1 | K28: 1
A29: 2022 | B29: 4 | C29: =+A29&"Q"&B29 -> 2022Q4 | D29: =+EOMONTH(DATE(A29,12,1),0) -> 44926 | E29: =+SUMIFS(Monthly!$D$2:$D$109,Monthly!$J$2:$J$109,Quarterly!D29) -> 2130498 | F29: =+AVERAGEIFS(Monthly!$E$2:$E$109,Monthly!$J$2:$J$109,Quarterly!D29) -> 113.23333 | G29: =+AVERAGEIFS(Monthly!$F$2:$F$109,Monthly!$J$2:$J$109,Quarterly!D29) -> 119.85333 | H29: =+AVERAGEIFS(Monthly!$G$2:$G$109,Monthly!$J$2:$J$109,Quarterly!D29) -> 6.3966667 | I29: 2823004.3 | J29: 1 | K29: 1
A30: 2023 | B30: 1 | C30: =+A30&"Q"&B30 -> 2023Q1 | D30: =+EOMONTH(DATE(A30,3,1),0) -> 45016 | E30: =+SUMIFS(Monthly!$D$2:$D$109,Monthly!$J$2:$J$109,Quarterly!D30) -> 2292905 | F30: =+AVERAGEIFS(Monthly!$E$2:$E$109,Monthly!$J$2:$J$109,Quarterly!D30) -> 123.3 | G30: =+AVERAGEIFS(Monthly!$F$2:$F$109,Monthly!$J$2:$J$109,Quarterly!D30) -> 121.64333 | H30: =+AVERAGEIFS(Monthly!$G$2:$G$109,Monthly!$J$2:$J$109,Quarterly!D30) -> 7.1066667 | I30: 2822499.2 | J30: 1 | K30: 0
A31: 2023 | B31: 2 | C31: =+A31&"Q"&B31 -> 2023Q2 | D31: =+EOMONTH(DATE(A31,6,1),0) -> 45107 | E31: =+SUMIFS(Monthly!$D$2:$D$109,Monthly!$J$2:$J$109,Quarterly!D31) -> 2415153 | F31: =+AVERAGEIFS(Monthly!$E$2:$E$109,Monthly!$J$2:$J$109,Quarterly!D31) -> 122.63333 | G31: =+AVERAGEIFS(Monthly!$F$2:$F$109,Monthly!$J$2:$J$109,Quarterly!D31) -> 122.69333 | H31: =+AVERAGEIFS(Monthly!$G$2:$G$109,Monthly!$J$2:$J$109,Quarterly!D31) -> 7.5133333 | I31: 2828169.1 | J31: 1 | K31: 0
A32: 2023 | B32: 3 | C32: =+A32&"Q"&B32 -> 2023Q3 | D32: =+EOMONTH(DATE(A32,9,1),0) -> 45199 | E32: =+SUMIFS(Monthly!$D$2:$D$109,Monthly!$J$2:$J$109,Quarterly!D32) -> 2153938 | F32: =+AVERAGEIFS(Monthly!$E$2:$E$109,Monthly!$J$2:$J$109,Quarterly!D32) -> 105.53333 | G32: =+AVERAGEIFS(Monthly!$F$2:$F$109,Monthly!$J$2:$J$109,Quarterly!D32) -> 123.39333 | H32: =+AVERAGEIFS(Monthly!$G$2:$G$109,Monthly!$J$2:$J$109,Quarterly!D32) -> 7.85 | I32: 2827642.3 | J32: 1 | K32: 0
A33: 2023 | B33: 4 | C33: =+A33&"Q"&B33 -> 2023Q4 | D33: =+EOMONTH(DATE(A33,12,1),0) -> 45291 | E33: =+SUMIFS(Monthly!$D$2:$D$109,Monthly!$J$2:$J$109,Quarterly!D33) -> 2232358 | F33: =+AVERAGEIFS(Monthly!$E$2:$E$109,Monthly!$J$2:$J$109,Quarterly!D33) -> 113.56667 | G33: =+AVERAGEIFS(Monthly!$F$2:$F$109,Monthly!$J$2:$J$109,Quarterly!D33) -> 123.61333 | H33: =+AVERAGEIFS(Monthly!$G$2:$G$109,Monthly!$J$2:$J$109,Quarterly!D33) -> 7.8066667 | I33: 2829175.5 | J33: 1 | K33: 0
A34: 2024 | B34: 1 | C34: =+A34&"Q"&B34 -> 2024Q1 | D34: =+EOMONTH(DATE(A34,3,1),0) -> 45382 | E34: =+SUMIFS(Monthly!$D$2:$D$109,Monthly!$J$2:$J$109,Quarterly!D34) -> 2397374 | F34: =+AVERAGEIFS(Monthly!$E$2:$E$109,Monthly!$J$2:$J$109,Quarterly!D34) -> 112.33333 | G34: =+AVERAGEIFS(Monthly!$F$2:$F$109,Monthly!$J$2:$J$109,Quarterly!D34) -> 123.86 | H34: =+AVERAGEIFS(Monthly!$G$2:$G$109,Monthly!$J$2:$J$109,Quarterly!D34) -> 7.9066667 | I34: 2836886.2 | J34: 1 | K34: 0
A35: 2024 | B35: 2 | C35: =+A35&"Q"&B35 -> 2024Q2 | D35: =+EOMONTH(DATE(A35,6,1),0) -> 45473 | E35: =+SUMIFS(Monthly!$D$2:$D$109,Monthly!$J$2:$J$109,Quarterly!D35) -> 2498063 | F35: =+AVERAGEIFS(Monthly!$E$2:$E$109,Monthly!$J$2:$J$109,Quarterly!D35) -> 109.73333 | G35: =+AVERAGEIFS(Monthly!$F$2:$F$109,Monthly!$J$2:$J$109,Quarterly!D35) -> 123.56 | H35: =+AVERAGEIFS(Monthly!$G$2:$G$109,Monthly!$J$2:$J$109,Quarterly!D35) -> 7.8233333 | I35: 2843366.6 | J35: 1 | K35: 0
A36: 2024 | B36: 3 | C36: =+A36&"Q"&B36 -> 2024Q3 | D36: =+EOMONTH(DATE(A36,9,1),0) -> 45565 | E36: =+SUMIFS(Monthly!$D$2:$D$109,Monthly!$J$2:$J$109,Quarterly!D36) -> 1958654 | F36: =+AVERAGEIFS(Monthly!$E$2:$E$109,Monthly!$J$2:$J$109,Quarterly!D36) -> 97.466667 | G36: =+AVERAGEIFS(Monthly!$F$2:$F$109,Monthly!$J$2:$J$109,Quarterly!D36) -> 123.82 | H36: =+AVERAGEIFS(Monthly!$G$2:$G$109,Monthly!$J$2:$J$109,Quarterly!D36) -> 7.78 | I36: 2856144.3 | J36: 1 | K36: 0
A37: 2024 | B37: 4 | C37: =+A37&"Q"&B37 -> 2024Q4 | D37: =+EOMONTH(DATE(A37,12,1),0) -> 45657 | E37: =+SUMIFS(Monthly!$D$2:$D$109,Monthly!$J$2:$J$109,Quarterly!D37) -> 2230449 | F37: =+AVERAGEIFS(Monthly!$E$2:$E$109,Monthly!$J$2:$J$109,Quarterly!D37) -> 101.5 | G37: =+AVERAGEIFS(Monthly!$F$2:$F$109,Monthly!$J$2:$J$109,Quarterly!D37) -> 124.10333 | H37: =+AVERAGEIFS(Monthly!$G$2:$G$109,Monthly!$J$2:$J$109,Quarterly!D37) -> 7.55 | I37: 2867125.1 | J37: 1 | K37: 0
